如果你在 Xcode 中浏览 NSString 类的文档页面，会看到很多方法的声明中包含了一个 throws 关键字，就像下面这样：

```swift
init(contentsOfFile path: String, encoding enc: UInt) throws
```

忽略报错的办法就是假装 throws 根本不存在：

```swift
let s = String(contentsOfFile: "XX", encoding: String.Encoding.utf8)
```

如果你在 playground 中输入以上代码，就会看到内容为 "Call can throw but is not marked with 'try'" 的错误信息。为了让编译器可以在语法上通过，我们必须添加一个 try 关键字。有三种风格的 try 写法，其中两种可以忽略错误，要捕获错误的话可以使用第三种。接下来我们先让这行代码的语法通过编译器：

```swift
let s = try? String(contentsOfFile: "XX", encoding: String.Encoding.utf8)
```

现在 playground 可以执行语句并显示结果为 nil。若你使用的是 try? 关键字，就会将所调用方法返回的类型转换为可选值。

我们可以在 if 语句中使用 try? 关键字，如果文件存在，那就执行一些操作，而且其内容也能够成功加载：

```swift
if let s = try? String(contentsOfFile: "XX", encoding: String.Encoding.utf8) {
    print("Content loaded")
} else {
    print("Failed to load contents of file")
}
```

如果你很肯定视图访问的文件存在而且内容能够被读取，可以用 try! 替换掉 try? 关键字，就像这样：

```swift
let s = try! String(contentsOfFile: "XX", encoding: String.Encoding.utf8)
```

**1. 捕获错误**

如果把 try? 作为 if let 语句的一部分，就能得知是否正确运行完毕，如果没有就采取其他操作。 try? 语句通过返回一个 nil 值间接告诉你运行遇到了错误，但这样就无法得知什么错误。必须在 do-catch 代码结构中使用 try 语句才可以，代码如下所示：

```swift
do {
    let s = try String(contentsOfFile: "XX", encoding: String.Encoding.utf8)
    print("Loaded content \(s)")
} catch {
    print(error)
}
```

**2. 抛出错误**

任何函数和方法都可以抛出一个错误，只要在声明中包含一个 throws 语句以表示它支持这个特性。抛出值可以是任何采用了 Error 协议的类型，比如 NSError 就是。

下面是一个自定义错误类型：

```swift
enum TriangleError: Error {
    case SideInvalid(reason: String)
    case AngleInvalid(reason: String)
}
```

在为函数补充错误检查功能之前，必须告诉编译器它可能会抛出一个错误。所以要在函数的定义语句中添加 throws 关键字。这个关键字必须放在函数的参数列表后面；如果有返回值类型，还必须放在它前面：

```swift
func calcThirdSide(_ side1: Double, side2: Double, angle: Double) throws -> Double {
    return sqrt(side1 * side1 + side2 * side2 - 2 * side1 * side2 * cos(angle))
}
```

现在我们可以开始为 calcThirdSide(side1:side2:angle:) 函数添加错误检查功能。将函数的代码改为如下所示：

```swift
func calcThirdSide(_ side1: Double, side2: Double, angle: Double) throws -> Double {
    if side1 <= 0 {
        throw TriangleError.SideInvalid(reason: "Side 1 must be >= 0, not \(side1)")
    }
    return sqrt(side1 * side1 + side2 * side2 - 2 * side1 * side2 * cos(angle))
}
```

**3. guard语句**

Swift 提供了另一种方式来表示这些错误检测，你可以使用 guard 语句来代替 if 语句。以下代码展示了如何使用 guard 重写包含 if 的 calcThirdSide(side1:side2:angle:) 函数：

```swift
func calcThirdSide(_ side1: Double, side2: Double, angle: Double) throws -> Double {
    guard side1 > 0 else {
        throw TriangleError.SideInvalid(reason: "Side 1 must be >= 0, not \(side1)")
    }
    
    guard side2 > 0 else {
        throw TriangleError.SideInvalid(reason: "Side 2 must be >= 0, not \(side2)")
    }
    
    guard angle >= 0 else {
        throw TriangleError.AngleInvalid(reason: "Angle must be >= 0, not \(angle)")
    }
    
    guard angle < Double.pi else {
        throw TriangleError.AngleInvalid(reason: "Angle must be <= π, not \(angle)")
    }
    
    return sqrt(side1 * side1 + side2 * side2 - 2 * side1 * side2 * cos(angle))
}
```

Guard 语句的代码后面必须跟上 else 关键字，它只有在检测不通过的时候执行。你可以认为 guard 的意思就是 “只有条件通过了才能执行后面的语句”，因此它必须和 if 语句所检测的条件相反。

一般形式的 guard 语句是这样的：

```swift
guard expression else {
    // guard 内容语句
    // 控制权移交到 guard 语句所在的结构范围之外
}

// 如果执行了 guard 代码内容，控制权一定不会到达此处
```

**4. 深入错误捕获**

一般来说，do-catch 语句可以拥有多个 catch 代码块，而每一个 catch 代码块都有一个表达式，抛出的错误根据匹配的内容，选择要执行的代码块。如果没有 catch 代码块匹配错误，就使用没有表达式的代码块；如果也没有这类代码块，错误就会抛给包含这个 do-catch 语句的函数或方法的调用者，而这个函数或方法必须声明包含一个 throws 关键字，表示可能会遇到错误。

在 playground 中将 do-catch 代码块改为如下内容：

```swift
do {
    let side3 = try calcThirdSide(-1, side2: 4, angle: Double.pi / 2)
    print(side3)
} catch let e as TriangleError {
    print(e)
}
```

如果想要针对不同的错误进行处理，只需要添加更多的状况。以下是示例代码：

```swift
do {
    let side3 = try calcThirdSide(-1, side2: 4, angle: Double.pi / 2)
    print(side3)
} catch TriangleError.SideInvalid(let reason) {
    print("Caught invalid side: \(reason)")
} catch {
    print("Caught \(error)")
}
```

如果存在像这样能捕获所有遗漏错误的代码块，必须是最后一个 catch 代码块，因此以下代码是不符合要求的：

```swift
do {
    let side3 = try calcThirdSide(-1, side2: 4, angle: Double.pi / 2)
    print(side3)
} catch {   // 这样将会导致后面的 catch 都不会执行到
    print("Caught \(error)")
} catch TriangleError.SideInvalid(let reason) {
    print("Caught invalid side: \(reason)")
}
```

为了能独立处理每个状况，可以分别为它们提供各自的 catch 代码块：

```swift
do {
    let side3 = try calcThirdSide(-1, side2: 4, angle: Double.pi / 2)
    print(side3)
} catch TriangleError.SideInvalid(let reason) {
    print("Caught invalid side: \(reason)")
} catch TriangleError.AngleInvalid(let reason) {
    print("Caught invalid side: \(reason)")
}
```

