`Python` 使用称为**异常**的特殊对象来管理程序执行期间发生的错误。每当发生让`Python` 不知所措的错误时，它都会创建一个异常对象。如果你编写了处理该异常的代码，程序将继续运行；如果你为对异常进行处理，程序将停止，并显示一个 traceback，其中包含有关异常的报告。

异常是使用 `try-except` 代码块处理的。`try-except` 代码块让 `Python` 执行指定的操作，同时告诉 `Python` 发生异常时怎么办。使用了 `try-except` 代码块时，即便出现异常，程序也将继续运行。

异常处理的简单语法格式如下：

```python
try:
    try_suite
except exception1 as variable1:
    exception_suite1
...
except exceptionN as variableN:
    exception_suiteN
```

> 注意：`as variable` 部分是可选的，我们可以只关心产生了某个特定的异常，而不关心其具体的消息文本。

例如：

```python
try:
	print(5/0)
except ZeroDivisionError:
	print("You can't divide by zero!")
```

或：

```python
s = input('enter an integer:')
try:
    i = int(s)
    print('valid integer entered:', i)
except ValueError as err:
    print(err)
```

