可以通过 `do { } catch {}` 语句捕获异常：

```swift
do {
  try canThrowAnError()
  // no error was thrown
} catch {
  // an error was thrown
}
```

do 语句创建了一个新的容器范围，可以让错误被传递到不止一个的 catch 分句里。

```swift
func makeASandwich() throws {
	// ...
}

do {
  try makeASandwich()
  eatASandwich()
} catch Error.MissingIngrediients(let ingredients) {
  buyGroceries(ingredients)
}
```

